Workbook

Sheet UPDATE
A1: DATE | B1: TRUCK# | C1: DIESEL | D1: TOLL | E1: MECHANIC | F1: RENTAL | G1: REGO | H1: INSURANCE | I1: TOTAL TRUCK COST
A2: 45975 | B2: 853 | E2: 142.857 | F2: 1000 | G2: 28.3 | H2: 428.57 | I2: =SUM(I2:I8) -> 0
A3: 45975 | B3: 881 | E3: 142.857 | F3: 500 | G3: 28.3 | H3: 428.57 | I3: =SUM(I3:I9) -> 0
A4: 45975 | B4: 855 | E4: 142.857 | G4: 28.3 | H4: 428.57 | I4: =SUM(I4:I10) -> 0
A5: 45975 | B5: 840 | E5: 142.857 | F5: 850 | G5: 28.3 | H5: 428.57 | I5: =SUM(I5:I11) -> 0
A6: 45975 | B6: 841 | E6: 142.857 | G6: 28.3 | H6: 428.57 | I6: =SUM(I6:I12) -> 0
A7: 45975 | B7: 672 | E7: 142.857 | G7: 28.3 | H7: 428.57 | I7: =SUM(I7:I13) -> 0
A8: 45975 | B8: 620 | E8: 142.857 | G8: 28.3 | H8: 428.57 | I8: =SUM(I8:I14) -> 0
A11: WEEK# | B11: DRIVER | C11: PAYSLIP | D11: BASE PAY | E11: BONUS | F11: NIGHT RUN | G11: LATE DEDUCTION | H11: AYUUTO DEDUCTION | I11: FINAL DRIVER PAY
A12: 49 | B12: ZAKY | D12: 1650 | H12: 625
A13: 49 | B13: SUHEN | D13: 1650 | H13: 312.5
A14: 49 | B14: SAMATAR | D14: 1650
A15: 49 | B15: SALEH | D15: 1625
A16: 49 | B16: RAMZI | D16: 1625 | H16: 937.5
A17: 49 | B17: SHERMAKER | D17: 1600
A18: 49 | B18: IMRAN | D18: 1600

Sheet DATA
A1: DATE | B1: TRUCK# | C1: DIESEL | D1: TOLL | E1: MECHANIC | F1: RENTAL | G1: REGO | H1: INSURANCE | I1: TOTAL TRUCK COST
A2: =UPDATE!A2 -> 45975 | B2: =UPDATE!B2 -> 853 | C2: 811 | D2: =UPDATE!D2 -> 0 | E2: =UPDATE!E2 -> 142.857 | F2: =UPDATE!F2 -> 1000 | G2: =UPDATE!G2 -> 28.3 | H2: =UPDATE!H2 -> 428.57 | I2: =SUM(UPDATE!B2:H2) -> 2452.727
A3: =UPDATE!A3 -> 45975 | B3: =UPDATE!B3 -> 881 | C3: 811 | D3: =UPDATE!D3 -> 0 | E3: =UPDATE!E3 -> 142.857 | F3: =UPDATE!F3 -> 500 | G3: =UPDATE!G3 -> 28.3 | H3: =UPDATE!H3 -> 428.57 | I3: =SUM(UPDATE!B3:H3) -> 1980.727
A4: =UPDATE!A4 -> 45975 | B4: =UPDATE!B4 -> 855 | C4: 553 | D4: =UPDATE!D4 -> 0 | E4: =UPDATE!E4 -> 142.857 | F4: =UPDATE!F4 -> 0 | G4: =UPDATE!G4 -> 28.3 | H4: =UPDATE!H4 -> 428.57 | I4: =SUM(UPDATE!B4:H4) -> 1454.727
A5: =UPDATE!A5 -> 45975 | B5: =UPDATE!B5 -> 840 | C5: 548 | D5: =UPDATE!D5 -> 0 | E5: =UPDATE!E5 -> 142.857 | F5: =UPDATE!F5 -> 850 | G5: =UPDATE!G5 -> 28.3 | H5: =UPDATE!H5 -> 428.57 | I5: =SUM(UPDATE!B5:H5) -> 2289.727
A6: =UPDATE!A6 -> 45975 | B6: =UPDATE!B6 -> 841 | C6: 260 | D6: =UPDATE!D6 -> 0 | E6: =UPDATE!E6 -> 142.857 | F6: =UPDATE!F6 -> 0 | G6: =UPDATE!G6 -> 28.3 | H6: =UPDATE!H6 -> 428.57 | I6: =SUM(UPDATE!B6:H6) -> 1440.727
A7: =UPDATE!A7 -> 45975 | B7: =UPDATE!B7 -> 672 | C7: 527.78 | D7: =UPDATE!D7 -> 0 | E7: =UPDATE!E7 -> 142.857 | F7: =UPDATE!F7 -> 0 | G7: =UPDATE!G7 -> 28.3 | H7: =UPDATE!H7 -> 428.57 | I7: =SUM(UPDATE!B7:H7) -> 1271.727
A8: =UPDATE!A8 -> 45975 | B8: =UPDATE!B8 -> 620 | C8: 471 | D8: =UPDATE!D8 -> 0 | E8: =UPDATE!E8 -> 142.857 | F8: =UPDATE!F8 -> 0 | G8: =UPDATE!G8 -> 28.3 | H8: =UPDATE!H8 -> 428.57 | I8: =SUM(UPDATE!B8:H8) -> 1219.727
A10: WEEK# | B10: DRIVER | C10: PAYSLIP | D10: BASE PAY | E10: BONUS | F10: NIGHT RUN | G10: LATE DEDUCTION | H10: AYUUTO DEDUCTION | I10: FINAL DRIVER PAY
A11: =UPDATE!A12 -> 49 | B11: =UPDATE!B12 -> ZAKY | C11: =UPDATE!C12 -> 0 | D11: =UPDATE!D12 -> 1650 | E11: 400 | F11: =UPDATE!F12 -> 0 | G11: =UPDATE!G12 -> 0 | H11: =UPDATE!H12 -> 625 | I11: =UPDATE!D12+UPDATE!E12+UPDATE!F12-UPDATE!G12-UPDATE!H12 -> 1025
A12: =UPDATE!A13 -> 49 | B12: =UPDATE!B13 -> SUHEN | C12: =UPDATE!C13 -> 0 | D12: =UPDATE!D13 -> 1650 | E12: =UPDATE!E13 -> 0 | F12: =UPDATE!F13 -> 0 | G12: =UPDATE!G13 -> 0 | H12: =UPDATE!H13 -> 312.5 | I12: =UPDATE!D13+UPDATE!E13+UPDATE!F13-UPDATE!G13-UPDATE!H13 -> 1337.5
A13: =UPDATE!A14 -> 49 | B13: =UPDATE!B14 -> SAMATAR | C13: =UPDATE!C14 -> 0 | D13: =UPDATE!D14 -> 1650 | E13: =UPDATE!E14 -> 0 | F13: =UPDATE!F14 -> 0 | G13: =UPDATE!G14 -> 0 | H13: =UPDATE!H14 -> 0 | I13: =UPDATE!D14+UPDATE!E14+UPDATE!F14-UPDATE!G14-UPDATE!H14 -> 1650
A14: =UPDATE!A15 -> 49 | B14: =UPDATE!B15 -> SALEH | C14: =UPDATE!C15 -> 0 | D14: =UPDATE!D15 -> 1625 | E14: =UPDATE!E15 -> 0 | F14: =UPDATE!F15 -> 0 | G14: =UPDATE!G15 -> 0 | H14: =UPDATE!H15 -> 0 | I14: =UPDATE!D15+UPDATE!E15+UPDATE!F15-UPDATE!G15-UPDATE!H15 -> 1625
A15: =UPDATE!A16 -> 49 | B15: =UPDATE!B16 -> RAMZI | C15: =UPDATE!C16 -> 0 | D15: =UPDATE!D16 -> 1625 | E15: =UPDATE!E16 -> 0 | F15: =UPDATE!F16 -> 0 | G15: =UPDATE!G16 -> 0 | H15: =UPDATE!H16 -> 937.5 | I15: =UPDATE!D16+UPDATE!E16+UPDATE!F16-UPDATE!G16-UPDATE!H16 -> 687.5
A16: =UPDATE!A17 -> 49 | B16: =UPDATE!B17 -> SHERMAKER | C16: =UPDATE!C17 -> 0 | D16: =UPDATE!D17 -> 1600 | E16: =UPDATE!E17 -> 0 | F16: =UPDATE!F17 -> 0 | G16: =UPDATE!G17 -> 0 | H16: =UPDATE!H17 -> 0 | I16: =UPDATE!D17+UPDATE!E17+UPDATE!F17-UPDATE!G17-UPDATE!H17 -> 1600
A17: =UPDATE!A18 -> 49 | B17: =UPDATE!B18 -> IMRAN | C17: =UPDATE!C18 -> 0 | D17: =UPDATE!D18 -> 1600 | E17: =UPDATE!E18 -> 0 | F17: =UPDATE!F18 -> 0 | G17: =UPDATE!G18 -> 0 | H17: =UPDATE!H18 -> 0 | I17: =UPDATE!D18+UPDATE!E18+UPDATE!F18-UPDATE!G18-UPDATE!H18 -> 1600

Sheet WEEKLY SUMMARY
A1: WEEK# | B1: TRUCK# | C1: TOTAL TRUCK COST | D1: FINAL DRIVER PAY | E1: TOTAL EXPENSES | F1: REVENUE | G1: PROFIT | H1: WEEK DATE
A2: 48 | B2: 853 | C2: =DATA!I2 -> 2452.727 | D2: =DATA!I11 -> 1025 | E2: =DATA!C2+DATA!D2+DATA!E2+DATA!F2+DATA!H2+DATA!E11+DATA!F11+DATA!H11 -> 3407.427 | F2: {=INDEX(DATA!$C$11:$C$17, ROW()-1) - C2 - D2} -> -3477.727 | G2: =F2 -> -3477.727 | H2: 45988
A3: 48 | B3: 881 | C3: =DATA!I3 -> 1980.727 | D3: =DATA!I12 -> 1337.5 | E3: =DATA!C3+DATA!D3+DATA!E3+DATA!F3+DATA!H3+DATA!E12+DATA!F12+DATA!H12 -> 2194.927 | F3: {=INDEX(DATA!$C$11:$C$17, ROW()-1) - C3 - D3} -> -3318.227 | G3: =F3 -> -3318.227
A4: 48 | B4: 855 | C4: =DATA!I4 -> 1454.727 | D4: =DATA!I13 -> 1650 | E4: =DATA!C4+DATA!D4+DATA!E4+DATA!F4+DATA!H4+DATA!E13+DATA!F13+DATA!H13 -> 1124.427 | F4: {=INDEX(DATA!$C$11:$C$17, ROW()-1) - C4 - D4} -> -3104.727 | G4: =F4 -> -3104.727
A5: 48 | B5: 840 | C5: =DATA!I5 -> 2289.727 | D5: =DATA!I14 -> 1625 | E5: =DATA!C5+DATA!D5+DATA!E5+DATA!F5+DATA!H5+DATA!E14+DATA!F14+DATA!H14 -> 1969.427 | F5: {=INDEX(DATA!$C$11:$C$17, ROW()-1) - C5 - D5} -> -3914.727 | G5: =F5 -> -3914.727
A6: 48 | B6: 841 | C6: =DATA!I6 -> 1440.727 | D6: =DATA!I15 -> 687.5 | E6: =DATA!C6+DATA!D6+DATA!E6+DATA!F6+DATA!H6+DATA!E15+DATA!F15+DATA!H15 -> 1768.927 | F6: {=INDEX(DATA!$C$11:$C$17, ROW()-1) - C6 - D6} -> -2128.227 | G6: =F6 -> -2128.227
A7: 48 | B7: 672 | C7: =DATA!I7 -> 1271.727 | D7: =DATA!I16 -> 1600 | E7: =DATA!C7+DATA!D7+DATA!E7+DATA!F7+DATA!H7+DATA!E16+DATA!F16+DATA!H16 -> 1099.207 | F7: {=INDEX(DATA!$C$11:$C$17, ROW()-1) - C7 - D7} -> -2871.727 | G7: =F7 -> -2871.727
A8: 48 | B8: 620 | C8: =DATA!I8 -> 1219.727 | D8: =DATA!I17 -> 1600 | E8: =DATA!C8+DATA!D8+DATA!E8+DATA!F8+DATA!H8+DATA!E17+DATA!F17+DATA!H17 -> 1042.427 | F8: {=INDEX(DATA!$C$11:$C$17, ROW()-1) - C8 - D8} -> -2819.727 | G8: =F8 -> -2819.727

Sheet PAYSLIPS
A1: PAYSLIP
A2: Week # | B2: =DATA!A11 -> 49 | C2: Driver | D2: =DATA!B11 -> ZAKY
A3: Base Pay | B3: =DATA!D11 -> 1650
A4: Bonus | B4: =DATA!E11 -> 400
A5: Night Run | B5: =DATA!F11 -> 0
A6: Late Deduction | B6: =DATA!G11 -> 0
A7: Ayuuto Deduction | B7: =DATA!H11 -> 625
A8: FINAL PAY | B8: =DATA!I11 -> 1025
A10: PAYSLIP
A11: Week # | B11: =DATA!A12 -> 49 | C11: Driver | D11: =DATA!B12 -> SUHEN
A12: Base Pay | B12: =DATA!D12 -> 1650
A13: Bonus | B13: =DATA!E12 -> 0
A14: Night Run | B14: =DATA!F12 -> 0
A15: Late Deduction | B15: =DATA!G12 -> 0
A16: Ayuuto Deduction | B16: =DATA!H12 -> 312.5
A17: FINAL PAY | B17: =DATA!I12 -> 1337.5
A19: PAYSLIP
A20: Week # | B20: =DATA!A13 -> 49 | C20: Driver | D20: =DATA!B13 -> SAMATAR
A21: Base Pay | B21: =DATA!D13 -> 1650
A22: Bonus | B22: =DATA!E13 -> 0
A23: Night Run | B23: =DATA!F13 -> 0
A24: Late Deduction | B24: =DATA!G13 -> 0
A25: Ayuuto Deduction | B25: =DATA!H13 -> 0
A26: FINAL PAY | B26: =DATA!I13 -> 1650
A28: PAYSLIP
A29: Week # | B29: =DATA!A14 -> 49 | C29: Driver | D29: =DATA!B14 -> SALEH
A30: Base Pay | B30: =DATA!D14 -> 1625
A31: Bonus | B31: =DATA!E14 -> 0
A32: Night Run | B32: =DATA!F14 -> 0
A33: Late Deduction | B33: =DATA!G14 -> 0
A34: Ayuuto Deduction | B34: =DATA!H14 -> 0
A35: FINAL PAY | B35: =DATA!I14 -> 1625
A37: PAYSLIP
A38: Week # | B38: =DATA!A15 -> 49 | C38: Driver | D38: =DATA!B15 -> RAMZI
A39: Base Pay | B39: =DATA!D15 -> 1625
A40: Bonus | B40: =DATA!E15 -> 0
A41: Night Run | B41: =DATA!F15 -> 0
A42: Late Deduction | B42: =DATA!G15 -> 0
A43: Ayuuto Deduction | B43: =DATA!H15 -> 937.5
A44: FINAL PAY | B44: =DATA!I15 -> 687.5
...

Sheet DASHBOARD
A1: Metric | B1: Amount
A2: Total Revenue | B2: ='WEEKLY SUMMARY'!F2+'WEEKLY SUMMARY'!F3+'WEEKLY SUMMARY'!F4+'WEEKLY SUMMARY'!F5+'WEEKLY SUMMARY'!F6+'WEEKLY SUMMARY'!F7+'WEEKLY SUMMARY'!F8 -> -21635.089
A3: Total Expenses | B3: ='WEEKLY SUMMARY'!E2+'WEEKLY SUMMARY'!E3+'WEEKLY SUMMARY'!E4+'WEEKLY SUMMARY'!E5+'WEEKLY SUMMARY'!E6+'WEEKLY SUMMARY'!E7+'WEEKLY SUMMARY'!E8 -> 12606.769
A4: Total Profit | B4: ='WEEKLY SUMMARY'!G2+'WEEKLY SUMMARY'!G3+'WEEKLY SUMMARY'!G4+'WEEKLY SUMMARY'!G5+'WEEKLY SUMMARY'!G6+'WEEKLY SUMMARY'!G7+'WEEKLY SUMMARY'!G8 -> -21635.089
A7: Truck# | B7: Revenue | C7: Expenses | D7: Profit
A8: ='WEEKLY SUMMARY'!B2 -> 853 | B8: ='WEEKLY SUMMARY'!F2 -> -3477.727 | C8: ='WEEKLY SUMMARY'!E2 -> 3407.427 | D8: ='WEEKLY SUMMARY'!G2 -> -3477.727
A9: ='WEEKLY SUMMARY'!B3 -> 881 | B9: ='WEEKLY SUMMARY'!F3 -> -3318.227 | C9: ='WEEKLY SUMMARY'!E3 -> 2194.927 | D9: ='WEEKLY SUMMARY'!G3 -> -3318.227
A10: ='WEEKLY SUMMARY'!B4 -> 855 | B10: ='WEEKLY SUMMARY'!F4 -> -3104.727 | C10: ='WEEKLY SUMMARY'!E4 -> 1124.427 | D10: ='WEEKLY SUMMARY'!G4 -> -3104.727
A11: ='WEEKLY SUMMARY'!B5 -> 840 | B11: ='WEEKLY SUMMARY'!F5 -> -3914.727 | C11: ='WEEKLY SUMMARY'!E5 -> 1969.427 | D11: ='WEEKLY SUMMARY'!G5 -> -3914.727
A12: ='WEEKLY SUMMARY'!B6 -> 841 | B12: ='WEEKLY SUMMARY'!F6 -> -2128.227 | C12: ='WEEKLY SUMMARY'!E6 -> 1768.927 | D12: ='WEEKLY SUMMARY'!G6 -> -2128.227
A13: ='WEEKLY SUMMARY'!B7 -> 672 | B13: ='WEEKLY SUMMARY'!F7 -> -2871.727 | C13: ='WEEKLY SUMMARY'!E7 -> 1099.207 | D13: ='WEEKLY SUMMARY'!G7 -> -2871.727
A14: ='WEEKLY SUMMARY'!B8 -> 620 | B14: ='WEEKLY SUMMARY'!F8 -> -2819.727 | C14: ='WEEKLY SUMMARY'!E8 -> 1042.427 | D14: ='WEEKLY SUMMARY'!G8 -> -2819.727
A16: MONTH | B16: Total REV | C16: Total PROF | D16: total EXP
A17: November | B17: =SUMIF('WEEK HISTORY'!E:E, A17, 'WEEK HISTORY'!B:B) -> -21635.089 | C17: =SUMIF('WEEK HISTORY'!E:E, A17, 'WEEK HISTORY'!D:D) -> -21635.089 | D17: =SUMIF('WEEK HISTORY'!E:E, A17, 'WEEK HISTORY'!C:C) -> 12606.769
A18: December | B18: =SUMIF('WEEK HISTORY'!E:E,#REF!, 'WEEK HISTORY'!B:B) -> 0 | C18: =SUMIF('WEEK HISTORY'!E:E,#REF!, 'WEEK HISTORY'!C:C) -> 0 | D18: =SUMIF('WEEK HISTORY'!E:E,#REF!, 'WEEK HISTORY'!C:C) -> 0
A19: January | B19: =SUMIF('WEEK HISTORY'!E:E,#REF!, 'WEEK HISTORY'!B:B) -> 0 | C19: =SUMIF('WEEK HISTORY'!E:E,#REF!, 'WEEK HISTORY'!C:C) -> 0 | D19: =SUMIF('WEEK HISTORY'!E:E,#REF!, 'WEEK HISTORY'!C:C) -> 0
A20: February | B20: =SUMIF('WEEK HISTORY'!E:E,#REF!, 'WEEK HISTORY'!B:B) -> 0 | C20: =SUMIF('WEEK HISTORY'!E:E,#REF!, 'WEEK HISTORY'!C:C) -> 0 | D20: =SUMIF('WEEK HISTORY'!E:E,#REF!, 'WEEK HISTORY'!C:C) -> 0
A21: March | B21: =SUMIF('WEEK HISTORY'!E:E,#REF!, 'WEEK HISTORY'!B:B) -> 0 | C21: =SUMIF('WEEK HISTORY'!E:E,#REF!, 'WEEK HISTORY'!C:C) -> 0 | D21: =SUMIF('WEEK HISTORY'!E:E,#REF!, 'WEEK HISTORY'!C:C) -> 0
A22: April | B22: =SUMIF('WEEK HISTORY'!E:E,#REF!, 'WEEK HISTORY'!B:B) -> 0 | C22: =SUMIF('WEEK HISTORY'!E:E,#REF!, 'WEEK HISTORY'!C:C) -> 0 | D22: =SUMIF('WEEK HISTORY'!E:E,#REF!, 'WEEK HISTORY'!C:C) -> 0
A23: May | B23: =SUMIF('WEEK HISTORY'!E:E,#REF!, 'WEEK HISTORY'!B:B) -> 0 | C23: =SUMIF('WEEK HISTORY'!E:E,#REF!, 'WEEK HISTORY'!C:C) -> 0 | D23: =SUMIF('WEEK HISTORY'!E:E,#REF!, 'WEEK HISTORY'!C:C) -> 0
A24: June | B24: =SUMIF('WEEK HISTORY'!E:E,#REF!, 'WEEK HISTORY'!B:B) -> 0 | C24: =SUMIF('WEEK HISTORY'!E:E,#REF!, 'WEEK HISTORY'!C:C) -> 0 | D24: =SUMIF('WEEK HISTORY'!E:E,#REF!, 'WEEK HISTORY'!C:C) -> 0
A25: July | B25: =SUMIF('WEEK HISTORY'!E:E,#REF!, 'WEEK HISTORY'!B:B) -> 0 | C25: =SUMIF('WEEK HISTORY'!E:E,#REF!, 'WEEK HISTORY'!C:C) -> 0 | D25: =SUMIF('WEEK HISTORY'!E:E,#REF!, 'WEEK HISTORY'!C:C) -> 0
A26: August | B26: =SUMIF('WEEK HISTORY'!E:E,#REF!, 'WEEK HISTORY'!B:B) -> 0 | C26: =SUMIF('WEEK HISTORY'!E:E,#REF!, 'WEEK HISTORY'!C:C) -> 0 | D26: =SUMIF('WEEK HISTORY'!E:E,#REF!, 'WEEK HISTORY'!C:C) -> 0
A27: September | B27: =SUMIF('WEEK HISTORY'!E:E,#REF!, 'WEEK HISTORY'!B:B) -> 0 | C27: =SUMIF('WEEK HISTORY'!E:E,#REF!, 'WEEK HISTORY'!C:C) -> 0 | D27: =SUMIF('WEEK HISTORY'!E:E,#REF!, 'WEEK HISTORY'!C:C) -> 0
A28: October | B28: =SUMIF('WEEK HISTORY'!E:E,#REF!, 'WEEK HISTORY'!B:B) -> 0 | C28: =SUMIF('WEEK HISTORY'!E:E,#REF!, 'WEEK HISTORY'!C:C) -> 0 | D28: =SUMIF('WEEK HISTORY'!E:E,#REF!, 'WEEK HISTORY'!C:C) -> 0
A29: November | B29: =SUMIF('WEEK HISTORY'!E:E,#REF!, 'WEEK HISTORY'!B:B) -> 0 | C29: =SUMIF('WEEK HISTORY'!E:E,#REF!, 'WEEK HISTORY'!C:C) -> 0 | D29: =SUMIF('WEEK HISTORY'!E:E,#REF!, 'WEEK HISTORY'!C:C) -> 0
A37: Week | B37: Total REV | C37: Total EXP | D37: Profit | E37: WEEK DATE
A38: 48 | B38: =SUM('WEEKLY SUMMARY'!F2:F8) -> -21635.089 | C38: =SUM('WEEKLY SUMMARY'!E2:E8) -> 12606.769 | D38: =SUM('WEEKLY SUMMARY'!G2:G8) -> -21635.089 | E38: 45988
A39: 49
A40: 50
A41: 51
A42: 52
A43: 53
A44: 54
A45: 55

Sheet WEEK HISTORY
A1: WEEK# | B1: TOTAL REVENUE | C1: TOTAL EXPENSES | D1: TOTAL PROFIT | E1: MONTH | F1: YEAR
A2: 48 | B2: =SUM('WEEKLY SUMMARY'!F2:F8) -> -21635.089 | C2: =SUM('WEEKLY SUMMARY'!E2:E8) -> 12606.769 | D2: =SUM('WEEKLY SUMMARY'!G2:G8) -> -21635.089 | E2: November | F2: 2025
A38: Week | B38: Total Rev | C38: Total EXP | D38: Profit | E38: WEEK DATE
A39: 48 | B39: 35432.67 | C39: 13667.78 | D39: 35432.67 | E39: 45988
